<?xml version="1.0" encoding="UTF-8"?>
<robot xmlns:xacro="http://ros.org/wiki/xacro">
   <xacro:property name="M_SCALE" value="0.001"/>
   <xacro:property name="M_PI" value="3.14159"/>
   
   <xacro:include filename="$(find widowx_arm_description)/urdf/common_materials.xacro" />

   <xacro:macro name="widowx_arm" params="parent *origin">

      <!-- links -->

      <link name="arm_base_link">
         <visual>
            <origin xyz="0 0 0" rpy="0 0 0" />
            <geometry>
               <mesh filename="package://widowx_arm_description/meshes/base_link.stl"/>
            </geometry>
            <xacro:material_black />
	     </visual>
         <collision>
            <origin xyz="0 0 0" rpy="0 0 0" />
            <geometry>
               <mesh filename="package://widowx_arm_description/meshes/base_link.stl"/>
            </geometry>
         </collision>
         <inertial>
            <origin xyz="0 0 0" rpy="0 0 0" />
            <mass value="0.540142" />
            <inertia ixx="0.0021190000" iyy="0.0006925000" izz="0.0025280000" ixy="-0.0000172100" ixz="0.0000006389" iyz="0.0000461200" />
         </inertial>
      </link>

      <link name="shoulder_link">
         <visual>
            <origin xyz="0 0 0" rpy="0 0 0" />
            <geometry>
               <mesh filename="package://widowx_arm_description/meshes/shoulder_link.stl" />
            </geometry>
            <xacro:material_black />
         </visual>
         <collision>
            <origin xyz="0 0 0" rpy="0 0 0" />
            <geometry>
               <mesh filename="package://widowx_arm_description/meshes/shoulder_link.stl"/>
            </geometry>
         </collision>
         <inertial>
            <origin xyz="0.0 0.0 -0.04" rpy="0 0 0" />
            <mass value="0.061" />
            <inertia ixx="0.001" ixy="0.0" ixz="0.0" iyy="0.001" iyz="0.0" izz="0.001" />
         </inertial>
      </link>

      <link name="biceps_link">
         <visual>
            <origin xyz="0 0 0" rpy="0 0 0" />
            <geometry>
               <mesh filename="package://widowx_arm_description/meshes/biceps_link.new.stl" />
            </geometry>
            <xacro:material_black />
         </visual>
         <collision>
            <origin xyz="0 0 0" rpy="0 0 0" />
            <geometry>
               <mesh filename="package://widowx_arm_description/meshes/biceps_link.new.stl" />
            </geometry>
         </collision>
         <inertial>
            <origin xyz="0.006670 0.0 0.083394" rpy="0 0 0" />
            <mass value="3.62e-1" />
            <inertia ixx="0.001" ixy="0.0" ixz="0.0" iyy="0.001" iyz="0.0" izz="0.001" />
         </inertial>
      </link>

      <link name="forearm_link">
         <visual>
            <origin xyz="0 0 0" rpy="0 0 0" />
            <geometry>
               <mesh filename="package://widowx_arm_description/meshes/forearm_link.new.stl"/>
            </geometry>
           <xacro:material_black />
         </visual>
         <collision>
            <origin xyz="0 0 0" rpy="0 0 0" />
            <geometry>
               <mesh filename="package://widowx_arm_description/meshes/forearm_link.new.stl"/>
            </geometry>
         </collision>
         <inertial>
            <origin xyz="0.000018 0.0 0.090995" rpy="0 0 0" />
            <mass value="1.87e-1" />
            <inertia ixx="0.001" ixy="0.0" ixz="0.0" iyy="0.001" iyz="0.0" izz="0.001" />
         </inertial>
      </link>

      <link name="wrist_1_link">
         <visual>
            <origin xyz="0 0 0" rpy="0 0 0" />
            <geometry>
               <mesh filename="package://widowx_arm_description/meshes/wrist_1_link.stl"/>
            </geometry>
            <xacro:material_black />
         </visual>
         <collision>
            <origin xyz="0 0 0" rpy="0 0 0" />
            <geometry>
               <mesh filename="package://widowx_arm_description/meshes/wrist_1_link.stl"/>
            </geometry>
         </collision>
         <inertial>
            <origin xyz="-0.010852 0.0 0.048078" rpy="0 0 0" />
            <mass value="9.1e-2" />
            <inertia ixx="0.001" ixy="0.0" ixz="0.0" iyy="0.001" iyz="0.0" izz="0.001" />
         </inertial>
      </link>

      <link name="wrist_2_link">
         <visual>
            <origin xyz="0 0 0" rpy="0 0 0" />
            <geometry>
               <mesh filename="package://widowx_arm_description/meshes/wrist_2_link.new.stl"/>
            </geometry>
            <xacro:material_black />
         </visual>
         <collision>
            <origin xyz="0 0 0" rpy="0 0 0" />
            <geometry>
               <mesh filename="package://widowx_arm_description/meshes/wrist_2_link.new.stl"/>
            </geometry>
         </collision>
         <inertial>
            <origin xyz="-0.018000 0.0 0.01500 " rpy="0 0 0" />
            <mass value="6.3e-2" />
            <inertia ixx="0.001" ixy="0.0" ixz="0.0" iyy="0.001" iyz="0.0" izz="0.001" />
         </inertial>
      </link>

      <!-- gripper links -->

      <link name="gripper_rail_link">
         <visual>
            <origin xyz="0 0 0" rpy="0 0 1.57" />
            <geometry>
               <mesh filename="package://widowx_arm_description/meshes/gripper_rail_link.stl"/>
            </geometry>
            <xacro:material_black />
         </visual>
         <!--Removed for now due to problems with collision in Gazebo-->
         <!--collision>
            <origin xyz="0 0 0" rpy="0 0 1.57" />
            <geometry>
               <mesh filename="package://widowx_arm_description/meshes/gripper_rail_link.stl"/>
            </geometry>
         </collision-->
         <inertial>
            <origin xyz="0 0 0" rpy="0 0 0" />
            <mass value="7.0e-3" />
            <inertia ixx="0.001" ixy="0.0" ixz="0.0" iyy="0.001" iyz="0.0" izz="0.001" />
         </inertial>
      </link>

      <link name="gripper_1_link">
         <visual>
            <origin xyz="0 -0.0007 0" rpy="0 0 1.57" />
            <geometry>
               <mesh filename="package://widowx_arm_description/meshes/gripper_hand_fixed_link.stl"/>
            </geometry>
            <xacro:material_black />
         </visual>
         <collision>
            <origin xyz="0 -0.0007 0" rpy="0 0 1.57" />
            <geometry>
               <mesh filename="package://widowx_arm_description/meshes/gripper_hand_fixed_link.stl"/>
            </geometry>
         </collision>
         <inertial>
            <origin xyz="0.0 -0.008292 0.017304" rpy="0 0 0" />
            <mass value="8.0e-3" />
            <inertia ixx="0.001" ixy="0.0" ixz="0.0" iyy="0.001" iyz="0.0" izz="0.001" />
         </inertial>
      </link>

      <link name="gripper_2_link">
         <visual>
            <origin xyz="0 0.0007 0" rpy="0 0 -1.57" />
            <geometry>
               <mesh filename="package://widowx_arm_description/meshes/gripper_hand_fixed_link.stl"/>
            </geometry>
            <xacro:material_black />
         </visual>
         <collision>
            <origin xyz="0 0.0007 0" rpy="0 0 -1.57" />
            <geometry>
               <mesh filename="package://widowx_arm_description/meshes/gripper_hand_fixed_link.stl"/>
            </geometry>
         </collision>
         <inertial>
            <origin xyz="0.0 0.008292 0.017304" rpy="0 0 0" />
            <mass value="8.0e-3" />
            <inertia ixx="0.001" ixy="0.0" ixz="0.0" iyy="0.001" iyz="0.0" izz="0.001" />
         </inertial>
      </link>


      <!-- joints -->
      <joint name="arm_base_joint" type="fixed">
         <insert_block name="origin" />
         <parent link="${parent}" />
         <child link="arm_base_link"/>
      </joint>

      <joint name="joint_1" type="revolute">
         <origin xyz="0 0 ${M_SCALE*125}" rpy="0 0 0" />
         <parent link="arm_base_link" />
         <child link="shoulder_link" />
         <axis xyz="0 0 1" />
         <limit lower="-2.617" upper="2.617" effort="6" velocity="0.785" />
      </joint>

      <joint name="joint_2" type="revolute">
         <!--origin xyz="0.04825 0 0.14203" rpy="0 0 0" /-->
         <origin xyz="0 0 0" rpy="0 0 0" />
         <parent link="shoulder_link" />
         <child link="biceps_link" />
         <axis xyz="0 1 0" />
         <limit lower="-1.571" upper="1.571" effort="6" velocity="1.571" />
      </joint>

      <joint name="joint_3" type="revolute">
         <origin xyz="${M_SCALE*48.25} 0 ${M_SCALE*142.03}" rpy="0 ${M_PI/2.0} 0" />
         <parent link="biceps_link" />
         <child link="forearm_link" />
         <axis xyz="0 1 0" />
         <limit lower="-1.571" upper="1.571" effort="6" velocity="1.571" />
      </joint>

      <joint name="joint_4" type="revolute">
         <origin xyz="0 0 ${M_SCALE*142.03}" rpy="0 0 0" />
         <parent link="forearm_link" />
         <child link="wrist_1_link" />
         <axis xyz="0 1 0" />
         <limit lower="-1.745" upper="1.745" effort="6" velocity="1.571" />
      </joint>

      <joint name="joint_5" type="revolute">
         <origin xyz="0 0 ${M_SCALE*71.5}" rpy="0 0 0" />
         <parent link="wrist_1_link" />
         <child link="wrist_2_link" />
         <axis xyz="0 0 1" />
         <limit lower="-2.617" upper="2.617" effort="6" velocity="1.571" />
      </joint>

      <joint name="joint_6" type="fixed">
         <origin xyz = "0 0 ${M_SCALE*43}" rpy="0 0 0" />
         <parent link="wrist_2_link" />
         <child link="gripper_rail_link" />
      </joint>

      <joint name="gripper_prismatic_joint_1" type="prismatic">
         <origin xyz="0 0 0" rpy="0 0 0" />
         <parent link="gripper_rail_link" />
         <child link="gripper_1_link" />
         <axis xyz="0 -1 0" />
         <limit lower="0.002" upper="0.031" effort="6" velocity="0.5" />
      </joint>

      <joint name="gripper_prismatic_joint_2" type="prismatic">
         <origin xyz="0 0 0" rpy="0 0 0" />
         <parent link="gripper_rail_link" />
         <child link="gripper_2_link" />
         <mimic joint="gripper_prismatic_joint_1" />
         <axis xyz="0 1 0" />
         <limit lower="0.002" upper="0.031" effort="6" velocity="0.5" />
      </joint> 

   </xacro:macro>

</robot>
